<?xml version="1.0"?>
<robot name="simple_arm">
  <!-- Base Link -->
  <link name="base_link">
    <visual>
      <geometry><box size="0.2 0.2 0.05"/></geometry>
      <material name="grey"><color rgba="0.5 0.5 0.5 1"/></material>
    </visual>
    <collision>
      <geometry><box size="0.2 0.2 0.05"/></geometry>
    </collision>
    <inertial>
      <mass value="1.0"/>
      <inertia ixx="0.01" ixy="0" ixz="0" iyy="0.01" iyz="0" izz="0.01"/>
    </inertial>
  </link>

  <!-- Joint 1 -->
  <joint name="joint1" type="revolute">
    <parent link="base_link"/>
    <child link="link1"/>
    <origin xyz="0 0 0.025"/>
    <axis xyz="0 0 1"/>
    <limit effort="100.0" lower="-3.14" upper="3.14" velocity="10.0"/>
  </joint>

  <!-- Link 1 -->
  <link name="link1">
    <visual>
      <origin xyz="0 0 0.15"/>
      <geometry><cylinder length="0.3" radius="0.03"/></geometry>
      <material name="green"><color rgba="0 1 0 1"/></material>
    </visual>
    <collision>
      <origin xyz="0 0 0.15"/>
      <geometry><cylinder length="0.3" radius="0.03"/></geometry>
    </collision>
    <inertial>
      <origin xyz="0 0 0.15"/>
      <mass value="1.0"/>
      <inertia ixx="0.01" ixy="0" ixz="0" iyy="0.01" iyz="0" izz="0.01"/>
    </inertial>
  </link>

  <!-- Joint 2 -->
  <joint name="joint2" type="revolute">
    <parent link="link1"/>
    <child link="link2"/>
    <origin xyz="0 0 0.3"/>
    <axis xyz="0 1 0"/>
    <limit effort="100.0" lower="-1.57" upper="1.57" velocity="10.0"/>
  </joint>

  <!-- Link 2 -->
  <link name="link2">
    <visual>
      <origin xyz="0 0 0.1"/>
      <geometry><cylinder length="0.2" radius="0.025"/></geometry>
      <material name="blue"><color rgba="0 0 1 1"/></material>
    </visual>
    <collision>
      <origin xyz="0 0 0.1"/>
      <geometry><cylinder length="0.2" radius="0.025"/></geometry>
    </collision>
    <inertial>
      <origin xyz="0 0 0.1"/>
      <mass value="0.5"/>
      <inertia ixx="0.01" ixy="0" ixz="0" iyy="0.01" iyz="0" izz="0.01"/>
    </inertial>
  </link>
</robot>